<sdf version='1.7'>
  <world name='default'>
    <light name='sun' type='directional'>
      <cast_shadows>1</cast_shadows>
      <pose>0 0 10 0 -0 0</pose>
      <diffuse>0.8 0.8 0.8 1</diffuse>
      <specular>0.2 0.2 0.2 1</specular>
      <attenuation>
        <range>1000</range>
        <constant>0.9</constant>
        <linear>0.01</linear>
        <quadratic>0.001</quadratic>
      </attenuation>
      <direction>-0.5 0.1 -0.9</direction>
      <spot>
        <inner_angle>0</inner_angle>
        <outer_angle>0</outer_angle>
        <falloff>0</falloff>
      </spot>
    </light>
    <model name='ground_plane'>
      <static>1</static>
      <link name='link'>
        <collision name='collision'>
          <geometry>
            <plane>
              <normal>0 0 1</normal>
              <size>100 100</size>
            </plane>
          </geometry>
          <surface>
            <contact>
              <collide_bitmask>65535</collide_bitmask>
              <ode/>
            </contact>
            <friction>
              <ode>
                <mu>100</mu>
                <mu2>50</mu2>
              </ode>
              <torsional>
                <ode/>
              </torsional>
            </friction>
            <bounce/>
          </surface>
          <max_contacts>10</max_contacts>
        </collision>
        <visual name='visual'>
          <cast_shadows>0</cast_shadows>
          <geometry>
            <plane>
              <normal>0 0 1</normal>
              <size>100 100</size>
            </plane>
          </geometry>
          <material>
            <script>
              <uri>file://media/materials/scripts/gazebo.material</uri>
              <name>Gazebo/Grey</name>
            </script>
          </material>
        </visual>
        <self_collide>0</self_collide>
        <enable_wind>0</enable_wind>
        <kinematic>0</kinematic>
      </link>
    </model>
    <gravity>0 0 -9.8</gravity>
    <magnetic_field>6e-06 2.3e-05 -4.2e-05</magnetic_field>
    <atmosphere type='adiabatic'/>
    <physics type='ode'>
      <max_step_size>0.001</max_step_size>
      <real_time_factor>1</real_time_factor>
      <real_time_update_rate>1000</real_time_update_rate>
    </physics>
    <scene>
      <ambient>0.4 0.4 0.4 1</ambient>
      <background>0.7 0.7 0.7 1</background>
      <shadows>1</shadows>
    </scene>
    <wind/>
    <spherical_coordinates>
      <surface_model>EARTH_WGS84</surface_model>
      <latitude_deg>0</latitude_deg>
      <longitude_deg>0</longitude_deg>
      <elevation>0</elevation>
      <heading_deg>0</heading_deg>
    </spherical_coordinates>
    <model name='binocular_laser_profile_scanner'>
      <joint name='world_joint' type='fixed'>
        <pose relative_to='__model__'>0 0 0 0 -0 0</pose>
        <parent>world</parent>
        <child>base_link</child>
      </joint>
      <link name='base_link'>
        <pose relative_to='world_joint'>0 0 0 0 -0 0</pose>
        <inertial>
          <pose>0.128012 0 0.01878 0 -0 0</pose>
          <mass>4.03488</mass>
          <inertia>
            <ixx>0.0328466</ixx>
            <ixy>-3.68285e-13</ixy>
            <ixz>-0.00197998</ixz>
            <iyy>0.0583372</iyy>
            <iyz>2.15791e-12</iyz>
            <izz>0.0901426</izz>
          </inertia>
        </inertial>
        <collision name='base_link_collision'>
          <pose>0 0 0 0 -0 0</pose>
          <geometry>
            <mesh>
              <scale>1 1 1</scale>
              <uri>/home/vboxuser/catkin_ws/src/binocular_laser_profile_scanner/meshes/base_link.STL</uri>
            </mesh>
          </geometry>
          <max_contacts>10</max_contacts>
          <surface>
            <contact>
              <ode/>
            </contact>
            <bounce/>
            <friction>
              <torsional>
                <ode/>
              </torsional>
              <ode/>
            </friction>
          </surface>
        </collision>
        <visual name='base_link_visual'>
          <pose>0 0 0 0 -0 0</pose>
          <geometry>
            <mesh>
              <scale>1 1 1</scale>
              <uri>/home/vboxuser/catkin_ws/src/binocular_laser_profile_scanner/meshes/base_link.STL</uri>
            </mesh>
          </geometry>
        </visual>
        <self_collide>0</self_collide>
        <enable_wind>0</enable_wind>
        <kinematic>0</kinematic>
      </link>
      <joint name='motor_joint' type='revolute'>
        <pose relative_to='base_link'>0.18 0 0.0682 3.14159 1.57079 3.14159</pose>
        <parent>base_link</parent>
        <child>motor_link</child>
        <axis>
          <xyz>0 0 1</xyz>
          <limit>
            <lower>0</lower>
            <upper>3.142</upper>
            <effort>1000</effort>
            <velocity>0.1</velocity>
          </limit>
          <dynamics>
            <spring_reference>0</spring_reference>
            <spring_stiffness>0</spring_stiffness>
          </dynamics>
        </axis>
      </joint>
      <link name='motor_link'>
        <pose relative_to='motor_joint'>0 0 0 0 -0 0</pose>
        <inertial>
          <pose>-0.015538 0.148369 -0.147865 0 -0 0</pose>
          <mass>0.111068</mass>
          <inertia>
            <ixx>0.00089861</ixx>
            <ixy>3.85219e-05</ixy>
            <ixz>-5.5484e-05</ixz>
            <iyy>0.000667507</iyy>
            <iyz>0.00027736</iyz>
            <izz>0.000278957</izz>
          </inertia>
        </inertial>
        <collision name='motor_link_collision'>
          <pose>0 0 0 0 -0 0</pose>
          <geometry>
            <mesh>
              <scale>1 1 1</scale>
              <uri>/home/vboxuser/catkin_ws/src/binocular_laser_profile_scanner/meshes/motor_link.STL</uri>
            </mesh>
          </geometry>
          <max_contacts>10</max_contacts>
          <surface>
            <contact>
              <ode/>
            </contact>
            <bounce/>
            <friction>
              <torsional>
                <ode/>
              </torsional>
              <ode/>
            </friction>
          </surface>
        </collision>
        <collision name='motor_link_fixed_joint_lump__scanner_body_link_collision_1'>
          <pose>-0.004 0.18003 -0.18005 -1.57079 -1.57079 3.14159</pose>
          <geometry>
            <mesh>
              <scale>1 1 1</scale>
              <uri>/home/vboxuser/catkin_ws/src/binocular_laser_profile_scanner/meshes/scanner_body_link.STL</uri>
            </mesh>
          </geometry>
          <max_contacts>10</max_contacts>
          <surface>
            <contact>
              <ode/>
            </contact>
            <bounce/>
            <friction>
              <torsional>
                <ode/>
              </torsional>
              <ode/>
            </friction>
          </surface>
        </collision>
        <collision name='motor_link_fixed_joint_lump__left_camera_link_collision_2'>
          <pose>-0.0215 0.148516 -0.106071 -3.14159 -0.71883 -1.5708</pose>
          <geometry>
            <mesh>
              <scale>1 1 1</scale>
              <uri>/home/vboxuser/catkin_ws/src/binocular_laser_profile_scanner/meshes/left_camera_link.STL</uri>
            </mesh>
          </geometry>
          <max_contacts>10</max_contacts>
          <surface>
            <contact>
              <ode/>
            </contact>
            <bounce/>
            <friction>
              <torsional>
                <ode/>
              </torsional>
              <ode/>
            </friction>
          </surface>
        </collision>
        <collision name='motor_link_fixed_joint_lump__right_camera_link_collision_3'>
          <pose>-0.0215 0.148516 -0.254029 -5e-06 -0.71883 1.5708</pose>
          <geometry>
            <mesh>
              <scale>1 1 1</scale>
              <uri>/home/vboxuser/catkin_ws/src/binocular_laser_profile_scanner/meshes/right_camera_link.STL</uri>
            </mesh>
          </geometry>
          <max_contacts>10</max_contacts>
          <surface>
            <contact>
              <ode/>
            </contact>
            <bounce/>
            <friction>
              <torsional>
                <ode/>
              </torsional>
              <ode/>
            </friction>
          </surface>
        </collision>
        <visual name='motor_link_visual'>
          <pose>0 0 0 0 -0 0</pose>
          <geometry>
            <mesh>
              <scale>1 1 1</scale>
              <uri>/home/vboxuser/catkin_ws/src/binocular_laser_profile_scanner/meshes/motor_link.STL</uri>
            </mesh>
          </geometry>
        </visual>
        <visual name='motor_link_fixed_joint_lump__scanner_body_link_visual_1'>
          <pose>-0.004 0.18003 -0.18005 -1.57079 -1.57079 3.14159</pose>
          <geometry>
            <mesh>
              <scale>1 1 1</scale>
              <uri>/home/vboxuser/catkin_ws/src/binocular_laser_profile_scanner/meshes/scanner_body_link.STL</uri>
            </mesh>
          </geometry>
        </visual>
        <visual name='motor_link_fixed_joint_lump__left_camera_link_visual_2'>
          <pose>-0.0215 0.148516 -0.106071 -3.14159 -0.71883 -1.5708</pose>
          <geometry>
            <mesh>
              <scale>1 1 1</scale>
              <uri>/home/vboxuser/catkin_ws/src/binocular_laser_profile_scanner/meshes/left_camera_link.STL</uri>
            </mesh>
          </geometry>
        </visual>
        <visual name='motor_link_fixed_joint_lump__right_camera_link_visual_3'>
          <pose>-0.0215 0.148516 -0.254029 -5e-06 -0.71883 1.5708</pose>
          <geometry>
            <mesh>
              <scale>1 1 1</scale>
              <uri>/home/vboxuser/catkin_ws/src/binocular_laser_profile_scanner/meshes/right_camera_link.STL</uri>
            </mesh>
          </geometry>
        </visual>
        <self_collide>0</self_collide>
        <enable_wind>0</enable_wind>
        <kinematic>0</kinematic>
      </link>
      <joint name='line_laser_joint' type='revolute'>
        <pose relative_to='motor_link'>-0.0215 0.153784 -0.18005 -1.57079 -1.57079 -3.14159</pose>
        <parent>motor_link</parent>
        <child>line_laser_link</child>
        <axis>
          <xyz>0 0 -1</xyz>
          <limit>
            <lower>0</lower>
            <upper>0</upper>
            <effort>0</effort>
            <velocity>0</velocity>
          </limit>
          <dynamics>
            <spring_reference>0</spring_reference>
            <spring_stiffness>0</spring_stiffness>
          </dynamics>
        </axis>
      </joint>
      <link name='line_laser_link'>
        <pose relative_to='line_laser_joint'>0 0 0 0 -0 0</pose>
        <inertial>
          <pose>-0 0 -0.01825 0 -0 0</pose>
          <mass>0.0040188</mass>
          <inertia>
            <ixx>4.8224e-07</ixx>
            <ixy>-2.6466e-23</ixy>
            <ixz>1.0799e-22</ixz>
            <iyy>4.8224e-07</iyy>
            <iyz>3.8191e-24</iyz>
            <izz>7.1033e-08</izz>
          </inertia>
        </inertial>
        <collision name='line_laser_link_collision'>
          <pose>0 0 0 0 -0 0</pose>
          <geometry>
            <mesh>
              <scale>1 1 1</scale>
              <uri>/home/vboxuser/catkin_ws/src/binocular_laser_profile_scanner/meshes/line_laser_link.STL</uri>
            </mesh>
          </geometry>
          <surface>
            <contact>
              <ode/>
            </contact>
            <friction>
              <ode/>
              <torsional>
                <ode/>
              </torsional>
            </friction>
            <bounce/>
          </surface>
          <max_contacts>10</max_contacts>
        </collision>
        <visual name='line_laser_link_visual'>
          <pose>0 0 0 0 -0 0</pose>
          <geometry>
            <mesh>
              <scale>1 1 1</scale>
              <uri>/home/vboxuser/catkin_ws/src/binocular_laser_profile_scanner/meshes/line_laser_link.STL</uri>
            </mesh>
          </geometry>
        </visual>
        <projector name='projector'>
          <pose>0 0 0 3.14159 -0 3.14159</pose>
          <texture>line_laser_5p.png</texture>
          <fov>2</fov>
          <near_clip>0.005</near_clip>
          <far_clip>1</far_clip>
        </projector>
        <self_collide>0</self_collide>
        <enable_wind>0</enable_wind>
        <kinematic>0</kinematic>
      </link>
      <joint name='rot_table_joint' type='revolute'>
        <pose relative_to='base_link'>0 0 0.04 0 -0 0</pose>
        <parent>base_link</parent>
        <child>rot_table_link</child>
        <axis>
          <xyz>0 0 -1</xyz>
          <limit>
            <lower>0</lower>
            <upper>6.284</upper>
            <effort>1000</effort>
            <velocity>0.1</velocity>
          </limit>
          <dynamics>
            <spring_reference>0</spring_reference>
            <spring_stiffness>0</spring_stiffness>
          </dynamics>
        </axis>
      </joint>
      <link name='rot_table_link'>
        <pose relative_to='rot_table_joint'>0 0 0 0 -0 0</pose>
        <inertial>
          <pose>0 -0 -0.005583 0 -0 0</pose>
          <mass>0.728064</mass>
          <inertia>
            <ixx>0.00399299</ixx>
            <ixy>-4.81482e-35</ixy>
            <ixz>5.7977e-20</ixz>
            <iyy>0.00399299</iyy>
            <iyz>6.22898e-36</iyz>
            <izz>0.00795454</izz>
          </inertia>
        </inertial>
        <collision name='rot_table_link_collision'>
          <pose>0 0 0 0 -0 0</pose>
          <geometry>
            <mesh>
              <scale>1 1 1</scale>
              <uri>/home/vboxuser/catkin_ws/src/binocular_laser_profile_scanner/meshes/rot_table_link.STL</uri>
            </mesh>
          </geometry>
          <max_contacts>10</max_contacts>
          <surface>
            <contact>
              <ode/>
            </contact>
            <bounce/>
            <friction>
              <torsional>
                <ode/>
              </torsional>
              <ode/>
            </friction>
          </surface>
        </collision>
        <visual name='rot_table_link_visual'>
          <pose>0 0 0 0 -0 0</pose>
          <geometry>
            <mesh>
              <scale>1 1 1</scale>
              <uri>/home/vboxuser/catkin_ws/src/binocular_laser_profile_scanner/meshes/rot_table_link.STL</uri>
            </mesh>
          </geometry>
        </visual>
        <self_collide>0</self_collide>
        <enable_wind>0</enable_wind>
        <kinematic>0</kinematic>
      </link>
      <plugin name='projector_controller' filename='libgazebo_ros_projector.so'>
        <projector>line_laser_link/projector</projector>
        <alwaysOn>1</alwaysOn>
        <updateRate>15.0</updateRate>
        <textureName>line_laser_5p.png</textureName>
        <textureTopicName>projector_controller/image</textureTopicName>
        <projectorTopicName>projector_controller/projector</projectorTopicName>
        <robotNamespace>/</robotNamespace>
      </plugin>
      <static>0</static>
      <plugin name='gazebo_ros_control' filename='libgazebo_ros_control.so'>
        <robotNamespace>/binocular_laser_profile_scanner</robotNamespace>
        <robotSimType>gazebo_ros_control/DefaultRobotHWSim</robotSimType>
      </plugin>
      <pose>0 0 0 0 -0 0</pose>
    </model>
    <state world_name='default'>
      <sim_time>476 963000000</sim_time>
      <real_time>952 61473327</real_time>
      <wall_time>1706701436 941071228</wall_time>
      <iterations>476963</iterations>
      <model name='binocular_laser_profile_scanner'>
        <pose>-0 0 0 0 -0 0</pose>
        <scale>1 1 1</scale>
        <link name='base_link'>
          <pose>-0 0 0 0 -0 0</pose>
          <velocity>0 0 -0 0 -0 0</velocity>
          <acceleration>0 -0 -0 0 -0 0</acceleration>
          <wrench>0 -0 -0 0 -0 0</wrench>
        </link>
        <link name='line_laser_link'>
          <pose>-4.9e-05 0.09487 0.19113 2.34542 2e-06 -4e-06</pose>
          <velocity>-0 -0 -0 -0 -0 -0</velocity>
          <acceleration>0 -0 -0 0 -1.4e-05 -1.1e-05</acceleration>
          <wrench>0 -0 -0 0 -0 0</wrench>
        </link>
        <link name='motor_link'>
          <pose>0.18 -0 0.0682 1.57081 0.796182 1.5708</pose>
          <velocity>-0 -0 0 0 -0 0</velocity>
          <acceleration>0 -0 -0 2.00652 0.578126 2.70554</acceleration>
          <wrench>0 -0 -0 0 -0 0</wrench>
        </link>
        <link name='rot_table_link'>
          <pose>-0 0 0.04 0 -0 0</pose>
          <velocity>-0 -0 -0 0 -0 0</velocity>
          <acceleration>0 -0 -0 0 -0 0</acceleration>
          <wrench>0 -0 -0 0 -0 0</wrench>
        </link>
      </model>
      <model name='ground_plane'>
        <pose>0 0 0 0 -0 0</pose>
        <scale>1 1 1</scale>
        <link name='link'>
          <pose>0 0 0 0 -0 0</pose>
          <velocity>0 0 0 0 -0 0</velocity>
          <acceleration>0 0 0 0 -0 0</acceleration>
          <wrench>0 0 0 0 -0 0</wrench>
        </link>
      </model>
      <light name='sun'>
        <pose>0 0 10 0 -0 0</pose>
      </light>
    </state>
    <gui fullscreen='0'>
      <camera name='user_camera'>
        <pose>5.06528 -4.90388 2.07708 0 0.275643 2.3562</pose>
        <view_controller>ortho</view_controller>
        <projection_type>orthographic</projection_type>
      </camera>
    </gui>
  </world>
</sdf>
